Workbook

Sheet C1019
W1: PAGE 1 OF 5
J4: HULL NO: | M4: C1019
I5: CUST REF:
C7: RESPONSIBILITY: | M7: ARL. Van Veen
AB8: Total | AC8: =MAX($C$10:C274)+1 -> 91
B9: COMMISSIONING DEFECTS Launch Date : | V9: TASK / JOB | W9: REPR BY (NAME) | X9: COMPL DT | Y9: T/L Sign | Z9: CE SIGN-OFF | AB9: Elec | AC9: =COUNTIF(V:V,"ELEC") -> 45
D10: SALOON | AB10: Plum | AC10: =COUNTIF(V:V,"PLUM") -> 25
C11: 1 | D11: inverter alarm not working | V11: ELEC | AB11: Mech | AC11: =COUNTIF(V:V,"MECH") -> 6
C12: 2 | D12: Autopilot motor Cross Wired | V12: ELEC | AB12: Other | AC12: =AC8-AC9-AC10-AC11 -> 15
C13: 3 | D13: mast wiring incomplete | V13: ELEC
C14: 4 | D14: deck light not working | V14: ELEC
C15: 5 | D15: incorrectly labeled acdc panel | V15: ELEC
C16: 6 | D16: missing deck wash label | V16: ELEC
C17: 7 | D17: multimeters freezing and needs to be updated | V17: ELEC
C18: 8 | D18: incorrect jump on shore 1 at acdc | V18: ELEC
C19: 9 | D19: dual shore power breaker light is wired on wrong side | V19: ELEC
C20: 10 | D20: TV lock pins incorrectly installed | V20: CARP
C21: 11 | D21: ACDC panel covers not fitted | V21: ELEC
C22: 12 | D22: bilge alarm panel not mounted | V22: ELEC
C23: 13 | D23: Incorrectly wired AC multimeter. Should measure genset and shore 1 not shore 2 | V23: ELEC
C24: 14 | D24: ACU ground wire not pulled through | V24: ELEC
... C35: 25 | D35: missing breaker labels on saloon DB | V35: ELEC
C49: =IF(ISTEXT(#REF!),MAX($C$10:C49)+1,"")
C50: =IF(ISTEXT(D50),MAX($C$10:C49)+1,"")
C51: =IF(ISTEXT(D51),MAX($C$10:C50)+1,"")
C52: =IF(ISTEXT(D52),MAX($C$10:C51)+1,"")
C53: =IF(ISTEXT(D53),MAX($C$10:C52)+1,"")
B54: The Commissioning Engineer has to list all defects found on the boat after launch within 24hrs.
B56: DATE: | K56: =TODAY() -> 45832
B58: COMMISSIONING ENGINEER: | K58: =$M$7 -> ARL. Van Veen | S58: SIGNATURE:
E60: 24. COMMISSIONING EXCEPTION SHEET | W60: Page 2 of 5
J63: HULL NO: | M63: =M4 -> C1019
I64: CUST REF:
C66: RESPONSIBILITY: | M66: ARL. Van Veen
B68: COMMISSIONING DEFECTS | V68: TASK / JOB | W68: REPR BY (NAME) | X68: COMPL DT | Y68: T/L Sign | Z68: CE SIGN-OFF
D69: STBD AFT CABIN AND HEADS
C70: =IF(ISTEXT(D70),MAX($C$10:C69)+1,"") -> 26 | D70: water pipe running over steering pulleys | V70: PLUM
C71: =IF(ISTEXT(D71),MAX($C$10:C70)+1,"") -> 27 | D71: outboard AC outlet is upside down | V71: CARP
C72: =IF(ISTEXT(D72),MAX($C$10:C71)+1,"") -> 28 | D72: untidy morse control cables inboard | V72: MECH
C73: =IF(ISTEXT(D73),MAX($C$10:C72)+1,"") -> 29 | D73: shower hot water kinked | V73: PLUM
...

Sheet C1018
W1: PAGE 1 OF 5
J4: HULL NO: | M4: C1018
I5: CUST REF:
C7: RESPONSIBILITY: | M7: ARL. Van Veen
AB8: Total | AC8: =MAX($C$10:C274)+1 -> 106
B9: COMMISSIONING DEFECTS Launch Date : | V9: TASK / JOB | W9: REPR BY (NAME) | X9: COMPL DT | Y9: T/L Sign | Z9: CE SIGN-OFF | AB9: Elec | AC9: =COUNTIF(V:V,"ELEC") -> 0
D10: SALOON | AB10: Plum | AC10: =COUNTIF(V:V,"PLUM") -> 0
C11: 1 | D11: saloon fridge not cooling | AB11: Mech | AC11: =COUNTIF(V:V,"MECH") -> 0
C12: 2 | D12: Nmma Label Needs To Be Mounted | AB12: Other | AC12: =AC8-AC9-AC10-AC11 -> 106
C13: 3 | D13: genset volts and hertz not correctly set
C14: 4 | D14: genset transfer breaker light not going on
C15: 5 | D15: mast wiring needs to be done
C16: 6 | D16: Saloon Door Needs To Be Set
C17: 7 | D17: missing clamp for fridge drain pipe
C18: 8 | D18: Oven cluster not working
C19: 9 | D19: bilge alarm panel not mounted
C20: 10 | D20: Saloon Clear Plastic Db Cover Not Mounted
C21: 11 | D21: Fire Blanket Not Fitted (Sf)
C22: 12 | D22: Co2 Sensor Not Mounted
C23: 13 | D23: incorrect acdc panel labels
C24: 14 | D24: incorrect colour code wire under helm on bus bar
... C37: 27 | D37: shore power 1 not working (incorrectly wired)
C49: =IF(ISTEXT(#REF!),MAX($C$10:C49)+1,"")
C50: =IF(ISTEXT(D50),MAX($C$10:C49)+1,"")
C51: =IF(ISTEXT(D51),MAX($C$10:C50)+1,"")
C52: =IF(ISTEXT(D52),MAX($C$10:C51)+1,"")
C53: =IF(ISTEXT(D53),MAX($C$10:C52)+1,"")
B54: The Commissioning Engineer has to list all defects found on the boat after launch within 24hrs.
B56: DATE: | K56: =TODAY() -> 45832
B58: COMMISSIONING ENGINEER: | K58: =$M$7 -> ARL. Van Veen | S58: SIGNATURE:
E60: 24. COMMISSIONING EXCEPTION SHEET | W60: Page 2 of 5
J63: HULL NO: | M63: =M4 -> C1018
I64: CUST REF:
C66: RESPONSIBILITY: | M66: ARL. Van Veen
B68: COMMISSIONING DEFECTS | V68: TASK / JOB | W68: REPR BY (NAME) | X68: COMPL DT | Y68: T/L Sign | Z68: CE SIGN-OFF
D69: STBD AFT CABIN AND HEADS
C70: =IF(ISTEXT(D70),MAX($C$10:C69)+1,"") -> 28 | D70: fuel pipes metal support frame loose
C71: =IF(ISTEXT(D71),MAX($C$10:C70)+1,"") -> 29 | D71: water heater drain pipe not cradled
C72: =IF(ISTEXT(D72),MAX($C$10:C71)+1,"") -> 30 | D72: helm cup holder drain not correctly installed
C73: =IF(ISTEXT(D73),MAX($C$10:C72)+1,"") -> 31 | D73: Basin Mixer Loose
...

Sheet C1013
W1: PAGE 1 OF 5
J4: HULL NO: | M4: C1013
I5: CUST REF:
C7: RESPONSIBILITY: | M7: ARL. Van Veen
AB8: Total | AC8: =MAX($C$10:C274)+1 -> 123
B9: COMMISSIONING DEFECTS Launch Date : | V9: TASK / JOB | W9: REPR BY (NAME) | X9: COMPL DT | Y9: T/L Sign | Z9: CE SIGN-OFF | AB9: Elec | AC9: =COUNTIF(V:V,"ELEC") -> 64
D10: SALOON | AB10: Plum | AC10: =COUNTIF(V:V,"PLUM") -> 37
C11: 1 | D11: buzzer not connected by helm | V11: ELEC | AB11: Mech | AC11: =COUNTIF(V:V,"MECH") -> 13
C12: 2 | D12: Nmma Label Needs To Be Mounted | V12: =_xlfn.XLOOKUP(D12,Common_Defect_List!A:A,Common_Defect_List!B:B,"") -> FA | AB12: Other | AC12: =AC8-AC9-AC10-AC11 -> 9
C13: 3 | D13: genset volts and hertz not correctly set | V13: ELEC
C14: 4 | D14: incomplete wiring by main DB | V14: ELEC
C15: 5 | D15: mast wiring needs to be done | V15: ELEC
C16: 6 | D16: Saloon Door Needs To Be Set | V16: =_xlfn.XLOOKUP(D16,Common_Defect_List!A:A,Common_Defect_List!B:B,"") -> CARP
C17: 7 | D17: missing clamp for fridge drain pipe | V17: PLUM
C18: 8 | D18: missing diodes by main DB | V18: ELEC
C19: 9 | D19: stbd fwd shower pump wire needs to be strapped to main db | V19: ELEC
C20: 10 | D20: Saloon Clear Plastic Db Cover Not Mounted | V20: CARP
C21: 11 | D21: Fire Blanket Not Fitted (Sf) | V21: =_xlfn.XLOOKUP(D21,Common_Defect_List!A:A,Common_Defect_List!B:B,"") -> CARP
C22: 12 | D22: Co2 Sensor Not Mounted | V22: =_xlfn.XLOOKUP(D22,Common_Defect_List!A:A,Common_Defect_List!B:B,"") -> CARP
C23: 13 | D23: incorrect acdc panel labels | V23: ELEC
C24: 14 | D24: curtacy lights incorrectly wired | V24: ELEC
C25: 15 | D25: missing labels for main breakers in floor | V25: ELEC
C26: 16 | D26: inverter network cable pulled out | V26: ELEC
C27: 17 | D27: no Co-X plugs fitted for VHF antenna | V27: ELEC
C28: 18 | D28: MFD needs to be updated | V28: =_xlfn.XLOOKUP(D28,Common_Defect_List!A:A,Common_Defect_List!B:B,"") -> ELEC
C29: 19 | D29: AC Multimeter needs to be programmed | V29: ELEC
C30: 20 | D30: No key tallies for saloon door fitted | V30: FA
C31: 21 | D31: Autopilot motor not working | V31: ELEC
C32: 22 | D32: DC multimeter freezing | V32: ELEC
C33: 23 | D33: incorrectly wired AC neutrals | V33: ELEC
C34: 24 | D34: DC multimeter arrow cross wired | V34: ELEC
C35: 25 | D35: deck light not working | V35: ELEC
C36: 26 | D36: AC cluster incorrectly wired | V36: ELEC
C37: 27 | D37: shore power 2 not working (incorrectly wired) | V37: ELEC
C38: 28 | D38: VHF antenna wire not pulled through from nav station | V38: ELEC
C39: 29 | D39: Galley Fridge Not Working | V39: ELEC
C40: 30 | D40: watermaker polarity incorrect | V40: ELEC
... C48: 38 | D48: stereo keeps tripping | V48: ELEC
C49: =IF(ISTEXT(#REF!),MAX($C$10:C49)+1,"")
C50: =IF(ISTEXT(D50),MAX($C$10:C49)+1,"")
...

Sheet C1017
W1: PAGE 1 OF 5
J4: HULL NO: | M4: C1017
I5: CUST REF:
C7: RESPONSIBILITY: | M7: ARL. Van Veen
AB8: Total | AC8: =MAX($C$10:C274)+1 -> 132
B9: COMMISSIONING DEFECTS Launch Date : | V9: TASK / JOB | W9: REPR BY (NAME) | X9: COMPL DT | Y9: T/L Sign | Z9: CE SIGN-OFF | AB9: Elec | AC9: =COUNTIF(V:V,"ELEC") -> 62
D10: SALOON | AB10: Plum | AC10: =COUNTIF(V:V,"PLUM") -> 37
C11: 1 | D11: incorrect wires (colour codes) used for light switches (multiple) | V11: ELEC | AB11: Mech | AC11: =COUNTIF(V:V,"MECH") -> 14
C12: 2 | D12: Nmma Label Needs To Be Mounted | V12: =_xlfn.XLOOKUP(D12,Common_Defect_List!A:A,Common_Defect_List!B:B,"") -> FA | AB12: Other | AC12: =AC8-AC9-AC10-AC11 -> 19
C13: 3 | D13: genset volts and hertz not correctly set | V13: ELEC
C14: 4 | D14: 2x missing downlights | V14: ELEC
C15: 5 | D15: mast wiring needs to be done | V15: ELEC
C16: 6 | D16: Saloon Door Needs To Be Set | V16: =_xlfn.XLOOKUP(D16,Common_Defect_List!A:A,Common_Defect_List!B:B,"") -> CARP
C17: 7 | D17: missing clamp for fridge drain pipe | V17: PLUM
C18: 8 | D18: saloon settee armrest bolts cut off too short | V18: CE
C19: 9 | D19: lifting platform isolator not mounted | V19: CARP
C20: 10 | D20: Saloon Clear Plastic Db Cover Not Mounted | V20: CARP
C21: 11 | D21: Fire Blanket Not Fitted (Sf) | V21: =_xlfn.XLOOKUP(D21,Common_Defect_List!A:A,Common_Defect_List!B:B,"") -> CARP
C22: 12 | D22: Co2 Sensor Not Mounted | V22: =_xlfn.XLOOKUP(D22,Common_Defect_List!A:A,Common_Defect_List!B:B,"") -> CARP
C23: 13 | D23: incorrect acdc panel labels | V23: ELEC
C24: 14 | D24: genset transfer causing finder behind ACDC to gitter | V24: ELEC
C25: 15 | D25: missing labels for main breakers in floor | V25: ELEC
C26: 16 | D26: 2x unused loose wires behind ACDC | V26: ELEC
C27: 17 | D27: no Co-X plugs fitted for VHF antenna | V27: ELEC
C28: 18 | D28: MFD needs to be updated | V28: =_xlfn.XLOOKUP(D28,Common_Defect_List!A:A,Common_Defect_List!B:B,"") -> ELEC
C29: 19 | D29: AC Multimeter needs to be programmed | V29: ELEC
C30: 20 | D30: No key tallies for saloon door fitted | V30: FA
C31: 21 | D31: Autopilot motor cross wired | V31: ELEC
C32: 22 | D32: DC multimeter freezing | V32: ELEC
C33: 23 | D33: Bad crimp on battery protect unit | V33: ELEC
C34: 24 | D34: house battery cables not properly routed and strapped | V34: ELEC
C35: 25 | D35: deck light not working | V35: ELEC
C36: 26 | D36: curtacy lights incorrectly wired | V36: ELEC
C37: 27 | D37: stbd engine battery voltage not showing on dc meter | V37: ELEC
C38: 28 | D38: VHF antenna wire not pulled through from nav station | V38: ELEC
C39: 29 | D39: horn button not working | V39: ELEC
C40: 30 | D40: Shore 2 not working (incorrect contactor wiring) | V40: ELEC
... C46: 36 | D46: Victron app on MFD not configured | V46: CE
C47: =IF(ISTEXT(D48),MAX($C$10:C47)+1,"")
C48: =IF(ISTEXT(#REF!),MAX($C$10:C48)+1,"")
...

Sheet C1015
W1: PAGE 1 OF 5
J4: HULL NO: | M4: C1015
I5: CUST REF:
C7: RESPONSIBILITY: | M7: ARL. Van Veen
AB8: Total | AC8: =MAX($C$10:C274)+1 -> 121
B9: COMMISSIONING DEFECTS Launch Date : | V9: TASK / JOB | W9: REPR BY (NAME) | X9: COMPL DT | Y9: T/L Sign | Z9: CE SIGN-OFF | AB9: Elec | AC9: =COUNTIF(V:V,"ELEC") -> 34
D10: SALOON | AB10: Plum | AC10: =COUNTIF(V:V,"PLUM") -> 41
C11: 1 | D11: ACDC covers not fitted | V11: ELEC | AB11: Mech | AC11: =COUNTIF(V:V,"MECH") -> 27
C12: =IF(ISTEXT(D12),MAX($C$10:C11)+1,"") -> 2 | D12: Nmma Label Needs To Be Mounted | V12: =_xlfn.XLOOKUP(D12,Common_Defect_List!A:A,Common_Defect_List!B:B,"") -> FA | AB12: Other | AC12: =AC8-AC9-AC10-AC11 -> 19
C13: =IF(ISTEXT(D13),MAX($C$10:C12)+1,"") -> 3 | D13: genset volts and hertz not correctly set | V13: ELEC
C14: =IF(ISTEXT(D14),MAX($C$10:C13)+1,"") -> 4 | D14: windlass not working on stbd ignition | V14: ELEC
C15: =IF(ISTEXT(D15),MAX($C$10:C14)+1,"") -> 5 | D15: mast wiring needs to be done | V15: ELEC
C16: =IF(ISTEXT(D16),MAX($C$10:C15)+1,"") -> 6 | D16: Saloon Door Needs To Be Set | V16: =_xlfn.XLOOKUP(D16,Common_Defect_List!A:A,Common_Defect_List!B:B,"") -> CARP
C17: =IF(ISTEXT(D17),MAX($C$10:C16)+1,"") -> 7 | D17: missing clamp for fridge drain pipe | V17: PLUM
C18: =IF(ISTEXT(D18),MAX($C$10:C17)+1,"") -> 8 | D18: Telly Mute Not Working | V18: =_xlfn.XLOOKUP(D18,Common_Defect_List!A:A,Common_Defect_List!B:B,"") -> ELEC
C19: =IF(ISTEXT(D19),MAX($C$10:C18)+1,"") -> 9 | D19: compass light not working | V19: ELEC
C20: =IF(ISTEXT(D20),MAX($C$10:C19)+1,"") -> 10 | D20: Saloon Clear Plastic Db Cover Not Mounted | V20: =_xlfn.XLOOKUP(D20,Common_Defect_List!A:A,Common_Defect_List!B:B,"") -> FA
C21: =IF(ISTEXT(D21),MAX($C$10:C20)+1,"") -> 11 | D21: Fire Blanket Not Fitted (Sf) | V21: =_xlfn.XLOOKUP(D21,Common_Defect_List!A:A,Common_Defect_List!B:B,"") -> CARP
C22: =IF(ISTEXT(D22),MAX($C$10:C21)+1,"") -> 12 | D22: Co2 Sensor Not Mounted | V22: =_xlfn.XLOOKUP(D22,Common_Defect_List!A:A,Common_Defect_List!B:B,"") -> CARP
C23: =IF(ISTEXT(D23),MAX($C$10:C22)+1,"") -> 13 | D23: incorrect acdc panel labels | V23: ELEC
C24: =IF(ISTEXT(D24),MAX($C$10:C23)+1,"") -> 14 | D24: reefing warning sign not fitted in galley | V24: FA
C25: =IF(ISTEXT(D25),MAX($C$10:C24)+1,"") -> 15 | D25: missing labels for main breakers in floor | V25: ELEC
C26: =IF(ISTEXT(D26),MAX($C$10:C25)+1,"") -> 16 | D26: house batteries brace loose | V26: CARP
C27: =IF(ISTEXT(D27),MAX($C$10:C26)+1,"") -> 17 | D27: no Co-X plugs fitted for VHF antenna | V27: ELEC
C28: =IF(ISTEXT(D28),MAX($C$10:C27)+1,"") -> 18 | D28: MFD needs to be updated | V28: =_xlfn.XLOOKUP(D28,Common_Defect_List!A:A,Common_Defect_List!B:B,"") -> ELEC
C29: =IF(ISTEXT(D29),MAX($C$10:C28)+1,"") -> 19 | D29: AC Multimeter needs to be programmed | V29: ELEC
C30: =IF(ISTEXT(D30),MAX($C$10:C29)+1,"") -> 20 | D30: No key tallies for saloon door fitted | V30: FA
C31: =IF(ISTEXT(D31),MAX($C$10:C30)+1,"") -> 21 | D31: Autopilot motor not connected | V31: ELEC
C32: =IF(ISTEXT(D32),MAX($C$10:C31)+1,"")
C33: =IF(ISTEXT(D34),MAX($C$10:C33)+1,"")
C34: =IF(ISTEXT(D35),MAX($C$10:C34)+1,"")
C35: =IF(ISTEXT(D36),MAX($C$10:C35)+1,"")
C36: =IF(ISTEXT(D37),MAX($C$10:C36)+1,"")
C37: =IF(ISTEXT(D38),MAX($C$10:C37)+1,"")
C38: =IF(ISTEXT(D39),MAX($C$10:C38)+1,"")
C39: =IF(ISTEXT(D40),MAX($C$10:C39)+1,"")
C40: =IF(ISTEXT(D41),MAX($C$10:C40)+1,"")
C41: =IF(ISTEXT(D42),MAX($C$10:C41)+1,"")
C42: =IF(ISTEXT(D43),MAX($C$10:C42)+1,"")
C43: =IF(ISTEXT(D44),MAX($C$10:C43)+1,"")
...

Sheet C1012
W1: PAGE 1 OF 5
J4: HULL NO: | M4: C1012
I5: CUST REF:
C7: RESPONSIBILITY: | M7: ARL. Van Veen
B9: COMMISSIONING DEFECTS Launch Date : | V9: TASK / JOB | W9: REPR BY (NAME) | X9: COMPL DT | Y9: T/L Sign | Z9: CE SIGN-OFF | AC9: =COUNTIF(V:V,"ELEC") -> 82
D10: SALOON
C11: 1 | D11: Telly Mute Not Working | V11: =_xlfn.XLOOKUP(D11,Common_Defect_List!A:A,Common_Defect_List!B:B,"") -> ELEC
C12: =IF(ISTEXT(D12),MAX($C$10:C11)+1,"") -> 2 | D12: Nmma Label Needs To Be Mounted | V12: =_xlfn.XLOOKUP(D12,Common_Defect_List!A:A,Common_Defect_List!B:B,"") -> FA
C13: =IF(ISTEXT(D13),MAX($C$10:C12)+1,"") -> 3 | D13: Aircon Switching On Wrong Pump | V13: =_xlfn.XLOOKUP(D13,Common_Defect_List!A:A,Common_Defect_List!B:B,"") -> ELEC
C14: =IF(ISTEXT(D14),MAX($C$10:C13)+1,"") -> 4 | D14: Incomplete Wiring Behind Acdc Panel | V14: =_xlfn.XLOOKUP(D14,Common_Defect_List!A:A,Common_Defect_List!B:B,"") -> ELEC
C15: =IF(ISTEXT(D15),MAX($C$10:C14)+1,"") -> 5 | D15: Incomplete Wiring At Main Saloon Db | V15: =_xlfn.XLOOKUP(D15,Common_Defect_List!A:A,Common_Defect_List!B:B,"") -> ELEC
C16: =IF(ISTEXT(D16),MAX($C$10:C15)+1,"") -> 6 | D16: Saloon Door Needs To Be Set | V16: =_xlfn.XLOOKUP(D16,Common_Defect_List!A:A,Common_Defect_List!B:B,"") -> CARP
C17: =IF(ISTEXT(D17),MAX($C$10:C16)+1,"") -> 7 | D17: Loose Wires Behind Acdc | V17: =_xlfn.XLOOKUP(D17,Common_Defect_List!A:A,Common_Defect_List!B:B,"") -> ELEC
C18: =IF(ISTEXT(D18),MAX($C$10:C17)+1,"") -> 8 | D18: Bilge Override Lights Not Mounted | V18: ELEC
C19: =IF(ISTEXT(D19),MAX($C$10:C18)+1,"") -> 9 | D19: Genset Isolator Switch Not Mounted | V19: =_xlfn.XLOOKUP(D19,Common_Defect_List!A:A,Common_Defect_List!B:B,"") -> CARP
C20: =IF(ISTEXT(D20),MAX($C$10:C19)+1,"") -> 10 | D20: Saloon Clear Plastic Db Cover Not Mounted | V20: =_xlfn.XLOOKUP(D20,Common_Defect_List!A:A,Common_Defect_List!B:B,"") -> FA
C21: =IF(ISTEXT(D21),MAX($C$10:C20)+1,"") -> 11 | D21: Fire Blanket Not Fitted (Sf) | V21: =_xlfn.XLOOKUP(D21,Common_Defect_List!A:A,Common_Defect_List!B:B,"") -> CARP
C22: =IF(ISTEXT(D22),MAX($C$10:C21)+1,"") -> 12 | D22: Co2 Sensor Not Mounted | V22: =_xlfn.XLOOKUP(D22,Common_Defect_List!A:A,Common_Defect_List!B:B,"") -> CARP
C23: =IF(ISTEXT(D23),MAX($C$10:C22)+1,"") -> 13 | D23: saloon door handle loose | V23: CARP
C24: =IF(ISTEXT(D24),MAX($C$10:C23)+1,"") -> 14 | D24: Inverter Not Programmed On Acdc | V24: =_xlfn.XLOOKUP(D24,Common_Defect_List!A:A,Common_Defect_List!B:B,"") -> ELEC
C25: =IF(ISTEXT(D25),MAX($C$10:C24)+1,"") -> 15 | D25: dual shore power switch light is on even with breaker off | V25: ELEC
C26: =IF(ISTEXT(D26),MAX($C$10:C25)+1,"") -> 16 | D26: genset transfer switch light is on even if breaker is off | V26: ELEC
C27: =IF(ISTEXT(D27),MAX($C$10:C26)+1,"") -> 17 | D27: genset transfer is not working | V27: ELEC
C28: =IF(ISTEXT(D28),MAX($C$10:C27)+1,"") -> 18 | D28: incorrect acdc panel labels | V28: ELEC
C29: =IF(ISTEXT(D29),MAX($C$10:C28)+1,"") -> 19 | D29: small conductor under large conductor x3 behind acdc panel | V29: ELEC
C30: =IF(ISTEXT(D30),MAX($C$10:C29)+1,"") -> 20 | D30: Inverter Alarm Not Working | V30: =_xlfn.XLOOKUP(D30,Common_Defect_List!A:A,Common_Defect_List!B:B,"") -> ELEC
C31: =IF(ISTEXT(D31),MAX($C$10:C30)+1,"") -> 21 | D31: acdc panel closing screws are too short | V31: CARP
C32: =IF(ISTEXT(D32),MAX($C$10:C31)+1,"") -> 22 | D32: missing negative bus cover in saloon DB | V32: ELEC
C33: =IF(ISTEXT(D33),MAX($C$10:C32)+1,"") -> 23 | D33: saloon downlights not working | V33: ELEC
C34: =IF(ISTEXT(D34),MAX($C$10:C33)+1,"") -> 24 | D34: 4x missing saloon downlights | V34: ELEC
C35: =IF(ISTEXT(D35),MAX($C$10:C34)+1,"") -> 25 | D35: curtacy lights not working | V35: ELEC
C36: =IF(ISTEXT(D36),MAX($C$10:C35)+1,"") -> 26 | D36: multiple loose ground wires in saloon floor | V36: ELEC
C37: =IF(ISTEXT(D37),MAX($C$10:C36)+1,"") -> 27 | D37: morse control ground wire not connected | V37: ELEC
C38: =IF(ISTEXT(D38),MAX($C$10:C37)+1,"") -> 28 | D38: lynxx blue cover missing | V38: ELEC
C39: =IF(ISTEXT(D39),MAX($C$10:C38)+1,"") -> 29 | D39: shunt blue cover missing | V39: ELEC
C40: =IF(ISTEXT(D40),MAX($C$10:C39)+1,"") -> 30 | D40: mast wiring is incomplete | V40: ELEC
C41: =IF(ISTEXT(D41),MAX($C$10:C40)+1,"") -> 31 | D41: missing mounting screws for main breakers in floor | V41: ELEC
C42: =IF(ISTEXT(D42),MAX($C$10:C41)+1,"") -> 32 | D42: missing labels for main breakers in floor | V42: ELEC
... C53: =IF(ISTEXT(D53),MAX($C$10:C52)+1,"") -> 43 | D53: backbone not terminated | V53: ELEC
C54: =IF(ISTEXT(D54),MAX($C$10:C53)+1,"")
...

Sheet C1016
W1: PAGE 1 OF 5
J4: HULL NO: | M4: C1016
I5: CUST REF:
C7: RESPONSIBILITY: | M7: ARL. Van Veen
B9: COMMISSIONING DEFECTS Launch Date : | V9: TASK / JOB | W9: REPR BY (NAME) | X9: COMPL DT | Y9: T/L Sign | Z9: CE SIGN-OFF | AC9: =COUNTIF(V:V,"ELEC") -> 0
D10: SALOON
C11: 1 | D11: genset isolator switch not mounted
C12: =IF(ISTEXT(D12),MAX($C$10:C11)+1,"") -> 2 | D12: grounding plate in port passgar bilge inboard is not connected to ground
C13: =IF(ISTEXT(D13),MAX($C$10:C12)+1,"") -> 3 | D13: 2x amplifiers not fitted
C14: =IF(ISTEXT(D14),MAX($C$10:C13)+1,"") -> 4 | D14: saloon fridge door is falling out
C15: =IF(ISTEXT(D15),MAX($C$10:C14)+1,"") -> 5 | D15: Saloon clear plastic DB cover not mounted
C16: =IF(ISTEXT(D16),MAX($C$10:C15)+1,"") -> 6 | D16: table top not installed
C17: =IF(ISTEXT(D17),MAX($C$10:C16)+1,"") -> 7 | D17: fire blanket not fitted (SF)
C18: =IF(ISTEXT(D18),MAX($C$10:C17)+1,"") -> 8 | D18: House batteries not booted
C19: =IF(ISTEXT(D19),MAX($C$10:C18)+1,"") -> 9 | D19: MFD not showing volts and amps of house battery
C20: =IF(ISTEXT(D20),MAX($C$10:C19)+1,"") -> 10 | D20: MFD showing stbd engine bilge is constantly running
C21: =IF(ISTEXT(D21),MAX($C$10:C20)+1,"") -> 11 | D21: Main DB not mounted
C22: =IF(ISTEXT(D22),MAX($C$10:C21)+1,"") -> 12 | D22: CO2 sensor not mounted
C23: =IF(ISTEXT(D23),MAX($C$10:C22)+1,"") -> 13 | D23: autopilot cross wired
... C35: =IF(ISTEXT(D35),MAX($C$10:C34)+1,"") -> 25 | D35: saloon door needs to be set
C36: =IF(ISTEXT(D36),MAX($C$10:C35)+1,"")
C37: =IF(ISTEXT(D37),MAX($C$10:C36)+1,"")
C38: =IF(ISTEXT(D38),MAX($C$10:C37)+1,"")
C39: =IF(ISTEXT(D39),MAX($C$10:C38)+1,"")
C40: =IF(ISTEXT(D40),MAX($C$10:C39)+1,"")
C41: =IF(ISTEXT(D41),MAX($C$10:C40)+1,"")
C42: =IF(ISTEXT(D42),MAX($C$10:C41)+1,"")
C43: =IF(ISTEXT(D43),MAX($C$10:C42)+1,"")
C44: =IF(ISTEXT(D44),MAX($C$10:C43)+1,"")
C45: =IF(ISTEXT(D45),MAX($C$10:C44)+1,"")
C46: =IF(ISTEXT(D46),MAX($C$10:C45)+1,"")
C47: =IF(ISTEXT(D47),MAX($C$10:C46)+1,"")
... C62: =IF(ISTEXT(D62),MAX($C$10:C61)+1,"")
B63: The Commissioning Engineer has to list all defects found on the boat after launch within 24hrs.
B65: DATE: | K65: =TODAY() -> 45832
B67: COMMISSIONING ENGINEER: | K67: =$M$7 -> ARL. Van Veen | S67: SIGNATURE:
E69: 24. COMMISSIONING EXCEPTION SHEET | W69: Page 2 of 5
J72: HULL NO: | M72: =M4 -> C1016
I73: CUST REF:
C75: RESPONSIBILITY: | M75: ARL. Van Veen
...

Sheet C1010
W1: PAGE 1 OF 5
J4: HULL NO: | M4: C1010
I5: CUST REF:
C7: RESPONSIBILITY: | M7: ARL. Van Veen
B9: COMMISSIONING DEFECTS Launch Date : | V9: TASK / JOB | W9: REPR BY (NAME) | X9: COMPL DT | Y9: T/L Sign | Z9: CE SIGN-OFF | AC9: =COUNTIF(V:V,"ELEC") -> 0
D10: SALOON
C11: 1 | D11: Feedback On Autopilot Breaker On Acdc
C12: =IF(ISTEXT(D12),MAX($C$10:C11)+1,"") -> 2 | D12: VHF antenna not connected (CO-X plugs on SF)
C13: =IF(ISTEXT(D13),MAX($C$10:C12)+1,"") -> 3 | D13: 2x amplifiers on SF
C14: =IF(ISTEXT(D14),MAX($C$10:C13)+1,"") -> 4 | D14: LPG monitor mounted skew
C15: =IF(ISTEXT(D15),MAX($C$10:C14)+1,"") -> 5 | D15: Saloon clear plastic DB cover not mounted
C16: =IF(ISTEXT(D16),MAX($C$10:C15)+1,"") -> 6 | D16: table top not installed
C17: =IF(ISTEXT(D17),MAX($C$10:C16)+1,"") -> 7 | D17: fire blanket not fitted (SF)
C18: =IF(ISTEXT(D18),MAX($C$10:C17)+1,"") -> 8 | D18: House batteries not booted
C19: =IF(ISTEXT(D19),MAX($C$10:C18)+1,"") -> 9 | D19: Lynxx 2 & shunt cover not mounted
C20: =IF(ISTEXT(D20),MAX($C$10:C19)+1,"") -> 10 | D20: helm alarm buzzer not mounted
C21: =IF(ISTEXT(D21),MAX($C$10:C20)+1,"") -> 11 | D21: Main DB not mounted
C22: =IF(ISTEXT(D22),MAX($C$10:C21)+1,"") -> 12 | D22: water pressure pump light on ACDC is flashing
C23: =IF(ISTEXT(D23),MAX($C$10:C22)+1,"") -> 13 | D23: saloon tap cross plumbed
... C32: =IF(ISTEXT(D32),MAX($C$10:C31)+1,"") -> 22 | D32: ACDC panel has no mounting skrews
C33: =IF(ISTEXT(D32),MAX($C$10:C32)+1,"") -> 23 | D33: bilge alarm panel loose
C34: =IF(ISTEXT(D34),MAX($C$10:C33)+1,"") -> 24 | D34: brken black plastic wire cover behind ACDC panel
C35: =IF(ISTEXT(D35),MAX($C$10:C34)+1,"") -> 25 | D35: aircon switching on wrong pump
C36: =IF(ISTEXT(D36),MAX($C$10:C35)+1,"") -> 26 | D36: Stbd aircon switches on the wrong LED on the ACDC panel
C37: =IF(ISTEXT(D37),MAX($C$10:C36)+1,"") -> 27 | D37: telly mute not working
C38: =IF(ISTEXT(D38),MAX($C$10:C37)+1,"") -> 28 | D38: autopilot cross wired
C39: =IF(ISTEXT(D39),MAX($C$10:C38)+1,"") -> 29 | D39: delay on 220V cluster from genset switch
C40: =IF(ISTEXT(D40),MAX($C$10:C39)+1,"") -> 30 | D40: CO2 sensor not mounted
C41: =IF(ISTEXT(D41),MAX($C$10:C40)+1,"")
C42: =IF(ISTEXT(D42),MAX($C$10:C41)+1,"")
C43: =IF(ISTEXT(D43),MAX($C$10:C42)+1,"")
C44: =IF(ISTEXT(D44),MAX($C$10:C43)+1,"")
C45: =IF(ISTEXT(D45),MAX($C$10:C44)+1,"")
C46: =IF(ISTEXT(D46),MAX($C$10:C45)+1,"")
C47: =IF(ISTEXT(D47),MAX($C$10:C46)+1,"")
C48: =IF(ISTEXT(D48),MAX($C$10:C47)+1,"")
C49: =IF(ISTEXT(D49),MAX($C$10:C48)+1,"")
C50: =IF(ISTEXT(D50),MAX($C$10:C49)+1,"")
C51: =IF(ISTEXT(D51),MAX($C$10:C50)+1,"")
C52: =IF(ISTEXT(D52),MAX($C$10:C51)+1,"")
...

Sheet C1009
W1: PAGE 1 OF 5
J4: HULL NO: | M4: C1009
I5: CUST REF:
C7: RESPONSIBILITY: | M7: ARL. Van Veen
B9: COMMISSIONING DEFECTS Launch Date : | V9: TASK / JOB | W9: REPR BY (NAME) | X9: COMPL DT | Y9: T/L Sign | Z9: CE SIGN-OFF | AC9: =COUNTIF(V:V,"ELEC") -> 36
D10: SALOON
C11: 1 | D11: david breaker is a different size to the other breakers | V11: ELEC
C12: =IF(ISTEXT(D12),MAX($C$10:C11)+1,"") -> 2 | D12: genset volts and hertz not set | V12: ELEC
C13: =IF(ISTEXT(D13),MAX($C$10:C12)+1,"") -> 3 | D13: bilge alarm panel not mounted on ACDC | V13: ELEC
C14: =IF(ISTEXT(D14),MAX($C$10:C13)+1,"") -> 4 | D14: outlet at TV not mounted | V14: CARP
C15: =IF(ISTEXT(D15),MAX($C$10:C14)+1,"") -> 5 | D15: missing boots on deck winch motors | V15: ELEC
C16: =IF(ISTEXT(D16),MAX($C$10:C15)+1,"") -> 6 | D16: curtacy light wiring wrong | V16: ELEC
C17: =IF(ISTEXT(D17),MAX($C$10:C16)+1,"") -> 7 | D17: under basin locker has no catch fitted | V17: CARP
C18: =IF(ISTEXT(D18),MAX($C$10:C17)+1,"") -> 8 | D18: nav desk front loosely mounted | V18: CARP
C19: =IF(ISTEXT(D19),MAX($C$10:C18)+1,"") -> 9 | D19: breakers not labeled at house batteries | V19: ELEC
C20: =IF(ISTEXT(D20),MAX($C$10:C19)+1,"") -> 10 | D20: house battery brace loose | V20: MECH
C21: =IF(ISTEXT(D21),MAX($C$10:C20)+1,"") -> 11 | D21: incorrect jump in main DB at AC wiring | V21: ELEC
C22: =IF(ISTEXT(D22),MAX($C$10:C21)+1,"") -> 12 | D22: missing cover on main negative DC terminal on main DB | V22: ELEC
C23: =IF(ISTEXT(D23),MAX($C$10:C22)+1,"") -> 13 | D23: main DB not mounted | V23: FA
... C29: =IF(ISTEXT(D29),MAX($C$10:C28)+1,"") -> 19 | D29: ACDC panel labels incomplete | V29: ELEC
C30: =IF(ISTEXT(D30),MAX($C$10:C29)+1,"")
C31: =IF(ISTEXT(D31),MAX($C$10:C30)+1,"")
C32: =IF(ISTEXT(D32),MAX($C$10:C31)+1,"")
C33: =IF(ISTEXT(D32),MAX($C$10:C32)+1,"")
C34: =IF(ISTEXT(D34),MAX($C$10:C33)+1,"")
C35: =IF(ISTEXT(D35),MAX($C$10:C34)+1,"")
C36: =IF(ISTEXT(D36),MAX($C$10:C35)+1,"")
C37: =IF(ISTEXT(D37),MAX($C$10:C36)+1,"")
C38: =IF(ISTEXT(D38),MAX($C$10:C37)+1,"")
C39: =IF(ISTEXT(D39),MAX($C$10:C38)+1,"")
C40: =IF(ISTEXT(D40),MAX($C$10:C39)+1,"")
C41: =IF(ISTEXT(D41),MAX($C$10:C40)+1,"")
C42: =IF(ISTEXT(D42),MAX($C$10:C41)+1,"")
C43: =IF(ISTEXT(D43),MAX($C$10:C42)+1,"")
C44: =IF(ISTEXT(D44),MAX($C$10:C43)+1,"")
C45: =IF(ISTEXT(D45),MAX($C$10:C44)+1,"")
... C62: =IF(ISTEXT(D62),MAX($C$10:C61)+1,"")
B63: The Commissioning Engineer has to list all defects found on the boat after launch within 24hrs.
B65: DATE: | K65: =TODAY() -> 45832
B67: COMMISSIONING ENGINEER: | K67: =$M$7 -> ARL. Van Veen | S67: SIGNATURE:
...

Sheet C1008
W1: PAGE 1 OF 5
J4: HULL NO: | M4: C1008
I5: CUST REF:
C7: RESPONSIBILITY: | M7: ARL. Van Veen
B9: COMMISSIONING DEFECTS Launch Date : | V9: TASK / JOB | W9: REPR BY (NAME) | X9: COMPL DT | Y9: T/L Sign | Z9: CE SIGN-OFF | AC9: =COUNTIF(V:V,"ELEC") -> 29
D10: SALOON
C11: 1 | D11: genset not charging boat | V11: ELEC
C12: =IF(ISTEXT(D12),MAX($C$10:C11)+1,"") -> 2 | D12: bilge low level has an alarm (it should not) | V12: ELEC
C13: =IF(ISTEXT(D13),MAX($C$10:C12)+1,"") -> 3 | D13: bilge indicator panel loose on acdc | V13: ELEC
C14: =IF(ISTEXT(D14),MAX($C$10:C13)+1,"") -> 4 | D14: david breaker not fitted | V14: ELEC
C15: =IF(ISTEXT(D15),MAX($C$10:C14)+1,"") -> 5 | D15: Inverter Not Programmed On Acdc | V15: ELEC
C16: =IF(ISTEXT(D16),MAX($C$10:C15)+1,"") -> 6 | D16: AC meter incorrectly programmed | V16: ELEC
C17: =IF(ISTEXT(D17),MAX($C$10:C16)+1,"") -> 7 | D17: DC meter indicator arrow cross wired | V17: ELEC
C18: =IF(ISTEXT(D18),MAX($C$10:C17)+1,"") -> 8 | D18: missing back cover on ACDC panel | V18: ELEC
C19: =IF(ISTEXT(D19),MAX($C$10:C18)+1,"") -> 9 | D19: Filter Tap Loose | V19: PLUM
C20: =IF(ISTEXT(D20),MAX($C$10:C19)+1,"") -> 10 | D20: HOB not igniting | V20: ELEC
C21: =IF(ISTEXT(D21),MAX($C$10:C20)+1,"") -> 11 | D21: downlights fitted skew | V21: FA
C22: =IF(ISTEXT(D22),MAX($C$10:C21)+1,"") -> 12 | D22: lynxx 2 covers not fitted | V22: ELEC
C23: =IF(ISTEXT(D23),MAX($C$10:C22)+1,"") -> 13 | D23: lynxx 2 inspection has no finger hole | V23: CARP
C24: =IF(ISTEXT(D24),MAX($C$10:C23)+1,"")
C25: =IF(ISTEXT(D25),MAX($C$10:C24)+1,"")
C26: =IF(ISTEXT(D26),MAX($C$10:C25)+1,"")
C27: =IF(ISTEXT(D27),MAX($C$10:C26)+1,"")
C28: =IF(ISTEXT(D28),MAX($C$10:C27)+1,"")
C29: =IF(ISTEXT(D29),MAX($C$10:C28)+1,"")
C30: =IF(ISTEXT(D30),MAX($C$10:C29)+1,"")
C31: =IF(ISTEXT(D31),MAX($C$10:C30)+1,"")
C32: =IF(ISTEXT(D32),MAX($C$10:C31)+1,"")
C33: =IF(ISTEXT(D32),MAX($C$10:C32)+1,"")
C34: =IF(ISTEXT(D34),MAX($C$10:C33)+1,"")
C35: =IF(ISTEXT(D35),MAX($C$10:C34)+1,"")
C36: =IF(ISTEXT(D36),MAX($C$10:C35)+1,"")
C37: =IF(ISTEXT(D37),MAX($C$10:C36)+1,"")
C38: =IF(ISTEXT(D38),MAX($C$10:C37)+1,"")
C39: =IF(ISTEXT(D39),MAX($C$10:C38)+1,"")
C40: =IF(ISTEXT(D40),MAX($C$10:C39)+1,"")
C41: =IF(ISTEXT(D41),MAX($C$10:C40)+1,"")
C42: =IF(ISTEXT(D42),MAX($C$10:C41)+1,"")
C43: =IF(ISTEXT(D43),MAX($C$10:C42)+1,"")
C44: =IF(ISTEXT(D44),MAX($C$10:C43)+1,"")
...

Sheet C1007
W1: PAGE 1 OF 5
J4: HULL NO: | M4: C1007
I5: CUST REF:
C7: RESPONSIBILITY: | M7: A. Labuschagne
B9: COMMISSIONING DEFECTS Launch Date : | V9: TASK / JOB | W9: REPR BY (NAME) | X9: COMPL DT | Y9: T/L Sign | Z9: CE SIGN-OFF | AC9: =COUNTIF(V:V,"DECK") -> 5
D10: SALOON
C11: 1 | D11: light wiring incorrect (all lights connected to cabin light breaker on acdc) | V11: ELEC
C12: =IF(ISTEXT(D12),MAX($C$10:C11)+1,"") -> 2 | D12: deck winches terminals not booted | V12: ELEC
C13: =IF(ISTEXT(D13),MAX($C$10:C12)+1,"") -> 3 | D13: protruding worm skrews on down lights | V13: ELEC
C14: =IF(ISTEXT(D14),MAX($C$10:C13)+1,"") -> 4 | D14: hob igniter is not working | V14: ELEC
C15: =IF(ISTEXT(D15),MAX($C$10:C14)+1,"") -> 5 | D15: main db breakers not labeled | V15: ELEC
C16: =IF(ISTEXT(D16),MAX($C$10:C15)+1,"") -> 6 | D16: stb aft aircon negative wiring incomplete at main db | V16: ELEC
C17: =IF(ISTEXT(D17),MAX($C$10:C16)+1,"") -> 7 | D17: incorrect ac wiring at main db | V17: ELEC
C18: =IF(ISTEXT(D18),MAX($C$10:C17)+1,"") -> 8 | D18: lynxx 2 terminal wires loose | V18: ELEC
C19: =IF(ISTEXT(D19),MAX($C$10:C18)+1,"") -> 9 | D19: lynxx 2 blue cover not fitted | V19: ELEC
C20: =IF(ISTEXT(D20),MAX($C$10:C19)+1,"") -> 10 | D20: lynxx 2 inspection has no finger cutout | V20: ELEC
C21: =IF(ISTEXT(D21),MAX($C$10:C20)+1,"") -> 11 | D21: incomplete loose wires at main db | V21: ELEC
C22: =IF(ISTEXT(D22),MAX($C$10:C21)+1,"") -> 12 | D22: house battery brace loose | V22: MECH
C23: =IF(ISTEXT(D23),MAX($C$10:C22)+1,"") -> 13 | D23: missing blade fuses at inverter relays in acdc | V23: ELEC
... C32: =IF(ISTEXT(D32),MAX($C$10:C31)+1,"") -> 22 | D32: loose ac outlet at tv bracket | V32: ELEC
C33: =IF(ISTEXT(D32),MAX($C$10:C32)+1,"") -> 23 | D33: carbon monoxide sensor not working | V33: ELEC
C34: =IF(ISTEXT(D34),MAX($C$10:C33)+1,"") -> 24 | D34: stb usb outlet not working | V34: ELEC
C35: =IF(ISTEXT(D35),MAX($C$10:C34)+1,"") -> 25 | D35: loose wires on minibus in ceiling | V35: ELEC
C36: =IF(ISTEXT(D36),MAX($C$10:C35)+1,"") -> 26 | D36: no grey raymic box for vhf mast connection | V36: ELEC
C37: =IF(ISTEXT(D37),MAX($C$10:C36)+1,"") -> 27 | D37: unterminated backbone in aft ceiling | V37: ELEC
C38: =IF(ISTEXT(D38),MAX($C$10:C37)+1,"") -> 28 | D38: ac cluster trips when all items are on on acdc | V38: ELEC
C39: =IF(ISTEXT(D39),MAX($C$10:C38)+1,"")
C40: =IF(ISTEXT(D40),MAX($C$10:C39)+1,"")
C41: =IF(ISTEXT(D41),MAX($C$10:C40)+1,"")
C42: =IF(ISTEXT(D42),MAX($C$10:C41)+1,"")
C43: =IF(ISTEXT(D43),MAX($C$10:C42)+1,"")
C44: =IF(ISTEXT(D44),MAX($C$10:C43)+1,"")
C45: =IF(ISTEXT(D45),MAX($C$10:C44)+1,"")
C46: =IF(ISTEXT(D46),MAX($C$10:C45)+1,"")
C47: =IF(ISTEXT(D47),MAX($C$10:C46)+1,"")
C48: =IF(ISTEXT(D48),MAX($C$10:C47)+1,"")
C49: =IF(ISTEXT(D49),MAX($C$10:C48)+1,"")
C50: =IF(ISTEXT(D50),MAX($C$10:C49)+1,"")
... C62: =IF(ISTEXT(D62),MAX($C$10:C61)+1,"")
B63: The Commissioning Engineer has to list all defects found on the boat after launch within 24hrs.
...

Sheet C1006
W1: PAGE 1 OF 5
J4: HULL NO: | M4: C1006
I5: CUST REF:
C7: RESPONSIBILITY: | M7: A. Labuschagne
B9: COMMISSIONING DEFECTS Launch Date : | V9: TASK / JOB | W9: REPR BY (NAME) | X9: COMPL DT | Y9: T/L Sign | Z9: CE SIGN-OFF
D10: SALOON
C11: 1 | D11: AR200 top plastic cover broken | V11: ELEC
C12: =IF(ISTEXT(D12),MAX($C$10:C11)+1,"") -> 2 | D12: TV mounting bracket loose | V12: DECK
C13: =IF(ISTEXT(D13),MAX($C$10:C12)+1,"") -> 3 | D13: feedback on fan breaker at ACDC | V13: ELEC
C14: =IF(ISTEXT(D14),MAX($C$10:C13)+1,"") -> 4 | D14: feedback on saloon breaker | V14: ELEC
C15: =IF(ISTEXT(D15),MAX($C$10:C14)+1,"") -> 5 | D15: saloon lights on when breaker is off | V15: ELEC
C16: =IF(ISTEXT(D16),MAX($C$10:C15)+1,"") -> 6 | D16: loose AC wiring behind ACDC | V16: ELEC
C17: =IF(ISTEXT(D17),MAX($C$10:C16)+1,"") -> 7 | D17: inverter alarm not working | V17: ELEC
C18: =IF(ISTEXT(D18),MAX($C$10:C17)+1,"") -> 8 | D18: loose wires at battery protect unit | V18: ELEC
C19: =IF(ISTEXT(D19),MAX($C$10:C18)+1,"") -> 9 | D19: poor crimps at battery protect unit | V19: ELEC
C20: =IF(ISTEXT(D20),MAX($C$10:C19)+1,"") -> 10 | D20: saloon and aft cockpit light switches cross wired | V20: ELEC
C21: =IF(ISTEXT(D21),MAX($C$10:C20)+1,"") -> 11 | D21: Loose Wires Behind Acdc | V21: ELEC
C22: =IF(ISTEXT(D22),MAX($C$10:C21)+1,"") -> 12 | D22: loose AC wiring behind ACDC | V22: ELEC
C23: =IF(ISTEXT(D23),MAX($C$10:C22)+1,"") -> 13 | D23: loose gnd bus connections on ac wiring of acdc | V23: ELEC
... C32: =IF(ISTEXT(D32),MAX($C$10:C31)+1,"") -> 22 | D32: no rail stopper on main DB in saloon | V32: ELEC
C33: =IF(ISTEXT(D32),MAX($C$10:C32)+1,"") -> 23 | D33: inverter not programmed | V33: ELEC
C34: =IF(ISTEXT(D34),MAX($C$10:C33)+1,"") -> 24 | D34: port engine battery not showing on yacht sense | V34: ELEC
C35: =IF(ISTEXT(D35),MAX($C$10:C34)+1,"") -> 25 | D35: feedback on dc breakers on ac dc | V35: ELEC
C36: =IF(ISTEXT(D36),MAX($C$10:C35)+1,"") -> 26 | D36: 2nd and 3rd ac clusters not working on acdc | V36: ELEC
C37: =IF(ISTEXT(D37),MAX($C$10:C36)+1,"") -> 27 | D37: genset water assist switching on at preheat | V37: ELEC
C38: =IF(ISTEXT(D38),MAX($C$10:C37)+1,"") -> 28 | D38: first ac cluster on acdc switches off when all aircons are switched on | V38: ELEC
C39: =IF(ISTEXT(D39),MAX($C$10:C38)+1,"") -> 29 | D39: loose screw on 2nd lynxx blue cover | V39: ELEC
C40: =IF(ISTEXT(D40),MAX($C$10:C39)+1,"") -> 30 | D40: missing bridges on main saloon DB | V40: ELEC
C41: =IF(ISTEXT(D41),MAX($C$10:C40)+1,"") -> 31 | D41: damaged red bridges in main DB in saloon | V41: ELEC
C42: =IF(ISTEXT(D42),MAX($C$10:C41)+1,"") -> 32 | D42: damaged manual bilge relay in main DB | V42: ELEC
C43: =IF(ISTEXT(D43),MAX($C$10:C42)+1,"") -> 33 | D43: saloon tap red/blue hot cold indicator installed skew | V43: PLUM
C44: =IF(ISTEXT(D44),MAX($C$10:C43)+1,"") -> 34 | D44: unterminated wire at main db in saloon | V44: ELEC
C45: =IF(ISTEXT(D45),MAX($C$10:C44)+1,"") -> 35 | D45: saloon tap weight installed wrong | V45: PLUM
... C52: =IF(ISTEXT(D52),MAX($C$10:C51)+1,"") -> 42 | D52: house bat isolator wires loose | V52: ELEC
C53: =IF(ISTEXT(D53),MAX($C$10:C52)+1,"")
C54: =IF(ISTEXT(D54),MAX($C$10:C53)+1,"")
C55: =IF(ISTEXT(D55),MAX($C$10:C54)+1,"")
C56: =IF(ISTEXT(D56),MAX($C$10:C55)+1,"")
C57: =IF(ISTEXT(D57),MAX($C$10:C56)+1,"")
C58: =IF(ISTEXT(D58),MAX($C$10:C57)+1,"")
...

Sheet C1005
E1: 24. COMMISSIONING EXCEPTION SHEET | W1: PAGE 1 OF 5
J4: HULL NO: | M4: C1005
I5: CUST REF:
C7: RESPONSIBILITY: | M7: A. Labuschagne
B9: COMMISSIONING DEFECTS Launch Date : | V9: TASK / JOB | W9: REPR BY (NAME) | X9: COMPL DT | Y9: T/L Sign | Z9: CE SIGN-OFF
D10: SALOON
C11: 1 | D11: Inverter not switching off at display | V11: ELEC
C12: =IF(ISTEXT(D12),MAX($C$10:C11)+1,"") -> 2 | D12: inverter switch not working | V12: ELEC
C13: =IF(ISTEXT(D13),MAX($C$10:C12)+1,"") -> 3 | D13: inverter not programmed on ACDC | V13: ELEC
C14: =IF(ISTEXT(D14),MAX($C$10:C13)+1,"") -> 4 | D14: inverter alarm not working | V14: ELEC
C15: =IF(ISTEXT(D15),MAX($C$10:C14)+1,"") -> 5 | D15: inverter alarm relays not fitted | V15: ELEC
C16: =IF(ISTEXT(D16),MAX($C$10:C15)+1,"") -> 6 | D16: watermaker not wired | V16: ELEC
C17: =IF(ISTEXT(D17),MAX($C$10:C16)+1,"") -> 7 | D17: touchlight in high voltage locker not working | V17: ELEC
C18: =IF(ISTEXT(D18),MAX($C$10:C17)+1,"") -> 8 | D18: loose wires behind ACDC | V18: ELEC
C19: =IF(ISTEXT(D19),MAX($C$10:C18)+1,"") -> 9 | D19: bilge override lights not working | V19: ELEC
C20: =IF(ISTEXT(D20),MAX($C$10:C19)+1,"") -> 10 | D20: prt high water not working | V20: ELEC
C21: =IF(ISTEXT(D21),MAX($C$10:C20)+1,"") -> 11 | D21: aircon pump not wired | V21: ELEC
C22: =IF(ISTEXT(D22),MAX($C$10:C21)+1,"") -> 12 | D22: GND wires behind ACDC are cut | V22: ELEC
C23: =IF(ISTEXT(D23),MAX($C$10:C22)+1,"") -> 13 | D23: Low water pressure at basin | V23: PLUM
... C44: =IF(ISTEXT(D44),MAX($C$10:C43)+1,"") -> 34 | D44: HOB fitted skew | V44: FA
D49: STBD AFT CABIN AND HEADS
C50: =IF(ISTEXT(D50),MAX($C$10:C49)+1,"") -> 35 | D50: aircon pump not wired | V50: ELEC
C51: =IF(ISTEXT(D51),MAX($C$10:C50)+1,"") -> 36 | D51: toilet salt/fresh water crossed | V51: ELEC
C52: =IF(ISTEXT(D52),MAX($C$10:C51)+1,"") -> 37 | D52: toilet fresh water solenoid not working | V52: ELEC
C53: =IF(ISTEXT(D53),MAX($C$10:C52)+1,"") -> 38 | D53: toilet hardup against wall | V53: PLUM
C54: =IF(ISTEXT(D54),MAX($C$10:C53)+1,"") -> 39 | D54: poor heat shrink on stb engine isolator switch | V54: ELEC
C55: =IF(ISTEXT(D55),MAX($C$10:C54)+1,"") -> 40 | D55: loose manual fire suppression wire | V55: ELEC
C56: =IF(ISTEXT(D56),MAX($C$10:C55)+1,"") -> 41 | D56: leak on stb water pressure pump plumbing | V56: PLUM
C57: =IF(ISTEXT(D57),MAX($C$10:C56)+1,"") -> 42 | D57: fridge compressor not mounted | V57: FA/PLUM
C58: =IF(ISTEXT(D58),MAX($C$10:C57)+1,"") -> 43 | D58: stb high water float alarm not working | V58: ELEC
C59: =IF(ISTEXT(D59),MAX($C$10:C58)+1,"") -> 44 | D59: fuel tank brace loose | V59: MECH
C60: =IF(ISTEXT(D60),MAX($C$10:C59)+1,"") -> 45 | D60: water tank brace loose | V60: PLUM
B63: The Commissioning Engineer has to list all defects found on the boat after launch within 24hrs.
B65: DATE: | K65: =TODAY() -> 45832
B67: COMMISSIONING ENGINEER: | K67: A. Labuschagne | S67: SIGNATURE:
E69: 24. COMMISSIONING EXCEPTION SHEET | W69: Page 2 of 5
J72: HULL NO: | M72: =M4 -> C1005
I73: CUST REF:
C75: RESPONSIBILITY: | M75: A. Labuschagne
B77: COMMISSIONING DEFECTS | V77: TASK / JOB | W77: REPR BY (NAME) | X77: COMPL DT | Y77: T/L Sign | Z77: CE SIGN-OFF
...

Sheet C1004
E1: 24. COMMISSIONING EXCEPTION SHEET | W1: PAGE 1 OF 5
J4: HULL NO: | M4: C1004
I5: CUST REF:
C7: RESPONSIBILITY: | M7: A. Labuschagne
B9: COMMISSIONING DEFECTS Launch Date : | V9: TASK / JOB | W9: REPR BY (NAME) | X9: COMPL DT | Y9: T/L Sign | Z9: CE SIGN-OFF
D10: SALOON
C11: 1 | D11: Genset Isolator switch loose | V11: ELEC
C12: 2 | D12: Dc M2 display not working | V12: ELEC
C13: 3 | D13: AC M2 display not working | V13: ELEC
C14: 4 | D14: Genset starter harness not wired | V14: ELEC
C15: 5 | D15: Genset starter harness plug broken | V15: ELEC
C16: 6 | D16: Fresh water pump signals not showing/working | V16: ELEC
C17: 7 | D17: Incorrect wiring on fresh water pumps at DB board | V17: ELEC
C18: 8 | D18: High level alarm present while present over-ride button | V18: ELEC
C19: 9 | D19: Loose DC wires on panel board | V19: ELEC
C20: 10 | D20: Loose AC wires on panel board | V20: ELEC
C21: 11 | D21: No Relays fitted for inverter alarm | V21: ELEC
C22: 12 | D22: Inverter alarm not working | V22: ELEC
... C41: 31 | D41: Missing boots on lewmar winches | V41: ELEC
B48: The Commissioning Engineer has to list all defects found on the boat after launch within 24hrs.
B50: DATE:
B52: COMMISSIONING ENGINEER: | K52: A. Labuschagne | S52: SIGNATURE:
E55: 24. COMMISSIONING EXCEPTION SHEET | W55: Page 2 of 5
J58: HULL NO: | M58: =$M$4 -> C1004
I59: CUST REF:
C61: RESPONSIBILITY: | M61: A. Labuschagne
B63: COMMISSIONING DEFECTS | V63: TASK / JOB | W63: REPR BY (NAME) | X63: COMPL DT | Y63: T/L Sign | Z63: CE SIGN-OFF
D64: STBD AFT Cabin & Heads
C65: 32 | D65: Loose fridge compressor | V65: CARP/PLUM
C66: 33 | D66: Fire suppression cable loose | V66: MECH
C67: 34 | D67: Leak on water heater | V67: PLUM
C68: 35 | D68: lights not working | V68: ELEC
C69: 36 | D69: No wires puled through for lights | V69: ELEC
C70: 37 | D70: Heads lights switch/wiring wrong | V70: ELEC
C71: 38 | D71: Inboard reading light not working | V71: ELEC
C72: 39 | D72: Outboard reading light not working | V72: ELEC
C73: 40 | D73: Leak from shower into bilge | V73: PLUM
C74: 41 | D74: Toilet water supply not working, Salt and Fresh | V74: ELEC/PLUM
C75: 42 | D75: Leak on toilet plumbing | V75: PLUM
C76: 43 | D76: Basin mixer loose | V76: PLUM
...

Sheet C1003
E1: 24. COMMISSIONING EXCEPTION SHEET | W1: PAGE 1 OF 5
J4: HULL NO: | M4: C1003
I5: CUST REF:
C7: RESPONSIBILITY: | M7: A. Labuschagne
B9: COMMISSIONING DEFECTS Launch Date : | V9: TASK / JOB | W9: REPR BY (NAME) | X9: COMPL DT | Y9: T/L Sign | Z9: CE SIGN-OFF
D10: SALOON
C11: 1 | D11: Down light switch cross wired
C12: =IF(ISTEXT(D12),MAX($C$10:C11)+1,"") -> 2 | D12: No labels of fridges on AC/DC panel
C13: =IF(ISTEXT(D13),MAX($C$10:C12)+1,"") -> 3 | D13: Down light grommet worm screws not flush
C14: =IF(ISTEXT(D14),MAX($C$10:C13)+1,"") -> 4 | D14: Yachtsense to be programmed
C15: =IF(ISTEXT(D15),MAX($C$10:C14)+1,"") -> 5 | D15: Missing stainless steel catch at AC/DC
C16: =IF(ISTEXT(D16),MAX($C$10:C15)+1,"") -> 6 | D16: Generator not giving power
C17: =IF(ISTEXT(D17),MAX($C$10:C16)+1,"") -> 7 | D17: Water pressure pump light not showing on AC/DC
C18: =IF(ISTEXT(D18),MAX($C$10:C17)+1,"") -> 8 | D18: Water pressure hot wired
C19: =IF(ISTEXT(D19),MAX($C$10:C18)+1,"") -> 9 | D19: HOB fitted skew
C20: =IF(ISTEXT(D20),MAX($C$10:C19)+1,"") -> 10 | D20: DB not mounted
C21: =IF(ISTEXT(D21),MAX($C$10:C20)+1,"") -> 11 | D21: Poor crimp on blue sea bus at DB compromised
C22: =IF(ISTEXT(D22),MAX($C$10:C21)+1,"") -> 12 | D22: Black wire to be terminated in DB
C23: =IF(ISTEXT(D23),MAX($C$10:C22)+1,"") -> 13 | D23: Poor heat shrink on AC wire in DB
... C33: =IF(ISTEXT(D33),MAX($C$10:C32)+1,"") -> 23 | D33: No network cable by MFD
C34: =IF(ISTEXT(D34),MAX($C$10:C33)+1,"")
C35: =IF(ISTEXT(D35),MAX($C$10:C34)+1,"")
C36: =IF(ISTEXT(D36),MAX($C$10:C35)+1,"")
D37: STBD AFT CABIN AND HEADS
C38: =IF(ISTEXT(D38),MAX($C$10:C37)+1,"") -> 24 | D38: Fan not connected
C39: =IF(ISTEXT(D41),MAX($C$10:C38)+1,"") -> 25 | D39: fridge compressor not secured
C40: =IF(ISTEXT(D42),MAX($C$10:C39)+1,"") -> 26 | D40: inboard reading light loose
C41: =IF(ISTEXT(D41),MAX($C$10:C40)+1,"") -> 27 | D41: manual suppression wire gromet loose
C42: =IF(ISTEXT(D42),MAX($C$10:C41)+1,"") -> 28 | D42: water heater not properly mounted
C43: =IF(ISTEXT(D43),MAX($C$10:C42)+1,"") -> 29 | D43: Fuel tank sensor wire loose
C44: =IF(ISTEXT(D44),MAX($C$10:C43)+1,"") -> 30 | D44: fuel pipes metal support loose
C45: =IF(ISTEXT(D45),MAX($C$10:C44)+1,"") -> 31 | D45: manual suppression wire nut loose
C46: =IF(ISTEXT(D46),MAX($C$10:C45)+1,"") -> 32 | D46: aft aircon loose
C47: =IF(ISTEXT(D47),MAX($C$10:C46)+1,"") -> 33 | D47: high level float not muting music
C48: =IF(ISTEXT(D48),MAX($C$10:C47)+1,"") -> 34 | D48: fridge drain not fitted properly
C49: =IF(ISTEXT(D49),MAX($C$10:C48)+1,"") -> 35 | D49: leak on shower plumbing
C50: =IF(ISTEXT(D50),MAX($C$10:C49)+1,"") -> 36 | D50: no terminator fitted in backbone in ceiling
C51: =IF(ISTEXT(D51),MAX($C$10:C50)+1,"") -> 37 | D51: basin mixer loose
C54: =IF(ISTEXT(#REF!),MAX($C$10:C53)+1,"") | D54: STBD MID CABIN & HEADS
C55: =IF(ISTEXT(D55),MAX($C$10:C54)+1,"") -> 38 | D55: basin mixer loose
...

Sheet Common_Defect_List
A1: Common Defect List | B1: Task Allocation | C1: Saloon | D1: Stbd Aft | E1: Stbd Mid | F1: Stbd Fwd | G1: Prt Aft | H1: Prt Passage | I1: Prt Fwd | J1: Aft Cockpit | K1: Prt Engine Room | L1: Stb Engine Room | M1: FWD COCKPIT, SIDE DECKS AND COACH ROOF | N1: Extras | R1: Area Allocation | S1: Task Allocation
A2: Leak On Basin Plumbing | B2: PLUM | C2: Yes | D2: Yes | E2: Yes | F2: Yes | G2: Yes | I2: Yes | R2: Yes | S2: PLUM
A3: Basin Mixer Loose | B3: PLUM | C3: Yes | D3: Yes | E3: Yes | F3: Yes | G3: Yes | I3: Yes | S3: ELEC
A4: Basin Cross Plumbed | B4: PLUM | C4: Yes | D4: Yes | E4: Yes | F4: Yes | G4: Yes | I4: Yes | S4: MECH
A5: Junction Box Not Labeled | B5: ELEC | C5: Yes | D5: Yes | E5: Yes | F5: Yes | G5: Yes | H5: Yes | I5: Yes | J5: Yes | K5: Yes | L5: Yes | M5: Yes | S5: FA
A6: Strip Lights Not Working | B6: ELEC | C6: Yes | D6: Yes | E6: Yes | F6: Yes | G6: Yes | H6: Yes | I6: Yes | J6: Yes | M6: Yes | S6: DECK
A7: Inverter Not Programmed On Acdc | B7: ELEC | C7: Yes | S7: CARP
A8: Inverter Alarm Not Working | B8: ELEC | C8: Yes
A9: Watermaker Not Wired | B9: ELEC | C9: Yes | I9: Yes
A10: Loose Wires Behind Acdc | B10: ELEC | C10: Yes
A11: Bilge Override Lights Not Working | B11: ELEC | C11: Yes
A12: Filter Tap Fitted Wrong (Too Tight) | B12: PLUM | C12: Yes
A13: Galley Fridge Not Working | B13: ELEC | C13: Yes
A14: Genset Isolator Switch Not Mounted | B14: CARP | C14: Yes
A15: 2X Amplifiers Not Fitted | B15: ELEC | C15: Yes
A16: Saloon Clear Plastic Db Cover Not Mounted | B16: FA | C16: Yes
A17: Table Top Not Installed | B17: CARP | C17: Yes
A18: Fire Blanket Not Fitted (Sf) | B18: CARP | C18: Yes
A19: House Batteries Not Booted | B19: ELEC | C19: Yes
A20: Mfd Not Showing Volts And Amps Of House Battery | B20: ELEC | C20: Yes | J20: Yes
A21: Co2 Sensor Not Mounted | B21: CARP | C21: Yes
A22: Autopilot Cross Wired | B22: ELEC | C22: Yes | J22: Yes
A23: Galley Fridge Compressor Loosely Mounted | B23: CARP | C23: Yes
A24: Saloon Tap Weight Mounted On Wrong Side Of Hose | B24: PLUM | C24: Yes
A25: Telly Mute Not Working | B25: ELEC | C25: Yes
A26: Nmma Label Needs To Be Mounted | B26: FA | C26: Yes
A27: Inverter Alarm Not Working | B27: ELEC | C27: Yes
A28: Aircon Switching On Wrong Pump | B28: ELEC | C28: Yes | D28: Yes | F28: Yes | G28: Yes | I28: Yes
A29: Incomplete Wiring Behind Acdc Panel | B29: ELEC | C29: Yes
A30: Incomplete Wiring At Main Saloon Db | B30: ELEC | C30: Yes
A31: Aircon Not Working | B31: ELEC | C31: Yes | D31: Yes | F31: Yes | G31: Yes | I31: Yes
A32: Saloon Door Needs To Be Set | B32: CARP | C32: Yes
A33: Aircon Not Draining | B33: PLUM | C33: Yes | D33: Yes | F33: Yes | G33: Yes | I33: Yes
A34: Incomplete Wiring On Db | B34: ELEC | C34: Yes | D34: Yes | G34: Yes | I34: Yes
A35: Speakers Not Working | B35: ELEC | C35: Yes | J35: Yes | M35: Yes
A36: Shower Mixer Loose | B36: PLUM | D36: Yes | E36: Yes | F36: Yes | G36: Yes | I36: Yes
A37: Swim Ladder Bolts Loose | B37: DECK | J37: Yes
A38: Ecu Not Labeled | B38: ELEC | K38: Yes | L38: Yes
A39: Topup Engine Fluids | B39: MECH | K39: Yes | L39: Yes
A40: Fuel Prefilter Pipe Clamps Loose | B40: MECH | K40: Yes | L40: Yes
...

Sheet Breakdown of areas
A1: Saloon | B1: Stbd Aft | C1: Stbd Mid | D1: Stbd Fwd | E1: Prt Aft | F1: Prt Passage | G1: Prt Fwd | H1: Aft Cockpit | I1: Prt Engine Room | J1: Stb Engine Room | K1: FWD COCKPIT, SIDE DECKS AND COACH ROOF | L1: Extras
A2: {=_xlfn._xlws.FILTER(Common_Defect_List!A:A,Common_Defect_List!C:C="Yes")} -> Leak On Basin Plumbing | B2: {=_xlfn._xlws.FILTER(Common_Defect_List!A:A,Common_Defect_List!D:D="Yes")} -> Leak On Basin Plumbing | C2: {=_xlfn._xlws.FILTER(Common_Defect_List!A:A,Common_Defect_List!E:E="Yes")} -> Leak On Basin Plumbing | D2: {=_xlfn._xlws.FILTER(Common_Defect_List!A:A,Common_Defect_List!F:F="Yes")} -> Leak On Basin Plumbing | E2: {=_xlfn._xlws.FILTER(Common_Defect_List!A:A,Common_Defect_List!G:G="Yes")} -> Leak On Basin Plumbing | F2: {=_xlfn._xlws.FILTER(Common_Defect_List!A:A,Common_Defect_List!H:H ="Yes")} -> Junction Box Not Labeled | G2: {=_xlfn._xlws.FILTER(Common_Defect_List!A:A,Common_Defect_List!I:I="Yes")} -> Leak On Basin Plumbing | H2: {=_xlfn._xlws.FILTER(Common_Defect_List!A:A,Common_Defect_List!J:J="Yes")} -> Junction Box Not Labeled | I2: {=_xlfn._xlws.FILTER(Common_Defect_List!A:A,Common_Defect_List!K:K="Yes")} -> Junction Box Not Labeled | J2: {=_xlfn._xlws.FILTER(Common_Defect_List!A:A,Common_Defect_List!L:L="Yes")} -> Junction Box Not Labeled | K2: {=_xlfn._xlws.FILTER(Common_Defect_List!A:A,Common_Defect_List!M:M="Yes")} -> Junction Box Not Labeled | L2: {=_xlfn._xlws.FILTER(Common_Defect_List!A:A,Common_Defect_List!N:N="Yes")} -> Aircon Display Covers (Sf)
A3: Basin Mixer Loose | B3: Basin Mixer Loose | C3: Basin Mixer Loose | D3: Basin Mixer Loose | E3: Basin Mixer Loose | F3: Strip Lights Not Working | G3: Basin Mixer Loose | H3: Strip Lights Not Working | I3: Ecu Not Labeled | J3: Ecu Not Labeled | K3: Strip Lights Not Working | L3: All Fire Extinguishers To Be Installed (Sf)
A4: Basin Cross Plumbed | B4: Basin Cross Plumbed | C4: Basin Cross Plumbed | D4: Basin Cross Plumbed | E4: Basin Cross Plumbed | F4: Waste Tank Leaking | G4: Basin Cross Plumbed | H4: Mfd Not Showing Volts And Amps Of House Battery | I4: Topup Engine Fluids | J4: Topup Engine Fluids | K4: Speakers Not Working
A5: Junction Box Not Labeled | B5: Junction Box Not Labeled | C5: Junction Box Not Labeled | D5: Junction Box Not Labeled | E5: Junction Box Not Labeled | F5: High Level Float Not Working | G5: Junction Box Not Labeled | H5: Autopilot Cross Wired | I5: Fuel Prefilter Pipe Clamps Loose | J5: Fuel Prefilter Pipe Clamps Loose | K5: Touch Light Not Working
A6: Strip Lights Not Working | B6: Strip Lights Not Working | C6: Strip Lights Not Working | D6: Strip Lights Not Working | E6: Strip Lights Not Working | F6: Low Level Float Not Working | G6: Strip Lights Not Working | H6: Speakers Not Working | I6: Expansion Tank Pipe Clamps Loose | J6: Expansion Tank Pipe Clamps Loose | K6: Jammer Labels Not Fitted
A7: Inverter Not Programmed On Acdc | B7: Aircon Switching On Wrong Pump | C7: Shower Mixer Loose | D7: Aircon Switching On Wrong Pump | E7: Aircon Switching On Wrong Pump | F7: Aircon Pump Not Working | G7: Watermaker Not Wired | H7: Swim Ladder Bolts Loose | I7: Morse Control Splitpins Not Properly Bent Open | J7: Morse Control Splitpins Not Properly Bent Open | K7: Pulleys And Rope Painter Needs To Be Installed
A8: Inverter Alarm Not Working | B8: Aircon Not Working | C8: Debree In Water Tank | D8: Aircon Not Working | E8: Aircon Not Working | F8: Touchlight In High Voltage Locker Not Working | G8: Aircon Switching On Wrong Pump | H8: Davit Skew | I8: Loose L-Bracket On Starter Motor | J8: Loose L-Bracket On Starter Motor | K8: Boom Labels Needs To Be Fitted
A9: Watermaker Not Wired | B9: Aircon Not Draining | C9: Toilet Seat Loose | D9: Aircon Not Draining | E9: Aircon Not Draining | F9: Shower Leaking Into Bilge | G9: Aircon Not Working | H9: Battery Link Not Working | I9: Steering Cable Loose | J9: Steering Cable Loose | K9: Oven Gas Shutoff Label Not Fitted
A10: Loose Wires Behind Acdc | B10: Incomplete Wiring On Db | C10: Water Tank Brace Loose | D10: Shower Mixer Loose | E10: Incomplete Wiring On Db | F10: Aircon Pump Pipes Leaking | G10: Aircon Not Draining | H10: Vhf Wire Not Pulled Through | I10: Missing Labels At Filters Outboard | J10: Missing Labels At Filters Outboard | K10: Genset Breaker Not Labeled
A11: Bilge Override Lights Not Working | B11: Shower Mixer Loose | C11: Toilet Roll Holder Loose | D11: Toilet Seat Loose | E11: Shower Mixer Loose | F11: Inverter Fans Not Working | G11: Incomplete Wiring On Db | H11: Hin Number Incorrect | I11: Missing Label On Battery | J11: Missing Label On Battery | K11: Gas Solenoid Not Wired
A12: Filter Tap Fitted Wrong (Too Tight) | B12: Debree In Water Tank | C12: Shower Sump Not Working | D12: Toilet Roll Holder Loose | E12: Debree In Water Tank | F12: Inverter Touch Light Not Working | G12: Shower Mixer Loose | H12: Hin Number Sticker Not Fitted | I12: Touch Light Not Working | J12: Touch Light Not Working
A13: Galley Fridge Not Working | B13: Toilet Seat Loose | C13: Shower Rose Leaking | D13: Shower Sump Not Working | E13: Toilet Seat Loose | F13: Aircon Connection Box Not Labeled | G13: Toilet Seat Loose | H13: Shore Power Label Not Fitted | I13: Fuel Clamps Loose At Bulkhead | J13: Fuel Clamps Loose At Bulkhead
A14: Genset Isolator Switch Not Mounted | B14: Water Tank Brace Loose | C14: Shower Mixer Leaking | D14: Shower Rose Leaking | E14: Water Tank Brace Loose | F14: Aircon Box Incorrectly Wired | G14: Toilet Roll Holder Loose | H14: R&C Decal Label / Dome Tag | I14: Engine Fuse Not Covered | J14: Engine Fuse Not Covered
A15: 2X Amplifiers Not Fitted | B15: Toilet Roll Holder Loose | C15: Waste Tank Leaking | D15: Shower Mixer Leaking | E15: Toilet Roll Holder Loose | F15: Missing Timmer Module For Aircon Relays | G15: Shower Sump Not Working | H15: Jammer Labels Not Fitted | I15: Morse Control Splitpins Not Properly Bent Open | J15: Morse Control Splitpins Not Properly Bent Open
A16: Saloon Clear Plastic Db Cover Not Mounted | B16: Shower Sump Not Working | C16: Leak On Toilet Plumbing | D16: Waste Tank Leaking | E16: Shower Sump Not Working | G16: Shower Rose Leaking | H16: Raymic Fitting Upside Down | I16: Battery Link Not Working | J16: Battery Link Not Working
A17: Table Top Not Installed | B17: Shower Rose Leaking | C17: Toilet Base Loose | D17: Leak On Toilet Plumbing | E17: Shower Rose Leaking | G17: Shower Mixer Leaking | H17: Engine Revs Do Not Align | I17: Battery Cover Not Fitted | J17: Battery Cover Not Fitted
A18: Fire Blanket Not Fitted (Sf) | B18: Shower Mixer Leaking | C18: High Level Float Not Working | D18: Toilet Base Loose | E18: Shower Mixer Leaking | G18: Touch Light Not Working | H18: No Teak Steps To Coach Roof Fitted | I18: Ecu Not Labeled | J18: Ecu Not Labeled
A19: House Batteries Not Booted | B19: Waste Tank Leaking | C19: Low Level Float Not Working | D19: Aircon Pump Not Working | E19: Leak On Toilet Plumbing | G19: Leak On Toilet Plumbing | H19: Mfd Needs To Be Updated | I19: Loose Wire On Starter Solenoid | J19: Loose Wire On Starter Solenoid
A20: Mfd Not Showing Volts And Amps Of House Battery | B20: Leak On Toilet Plumbing | C20: Toilet Anti-Syphen Leaking | D20: Toilet Anti-Syphen Leaking | E20: Fuel Tank Brace Loose | G20: Toilet Base Loose | I20: Galvanic Isolator Wires Loose | J20: Steering Bar Laying On Raw Fibre Glass
A21: Co2 Sensor Not Mounted | B21: Fuel Tank Brace Loose | C21: Toilet Fresh Water Solenoid Not Working | D21: Toilet Fresh Water Solenoid Not Working | E21: Fuel Clamps Loose At Bulkhead | G21: Toilet Anti-Syphen Leaking | I21: Steering Bar Laying On Raw Fibre Glass | J21: Alternator Negative Wire Not Connected
A22: Autopilot Cross Wired | B22: Fuel Clamps Loose At Bulkhead | C22: Waste Tank Indicator Not Working | D22: Waste Tank Indicator Not Working | E22: Toilet Base Loose | G22: Toilet Fresh Water Solenoid Not Working | I22: Alternator Negative Wire Not Connected | J22: Morse Control Cables Are Badly Routed
A23: Galley Fridge Compressor Loosely Mounted | B23: Toilet Base Loose | C23: Cabin Fan Not Working | D23: Cabin Fan Not Working | E23: Toilet Anti-Syphen Leaking | G23: Waste Tank Indicator Not Working | I23: Morse Control Cables Are Badly Routed | J23: Engine Harness Not Strapped Up
A24: Saloon Tap Weight Mounted On Wrong Side Of Hose | B24: High Level Float Not Working | C24: Waste Tank Indicator Light Not Fitted | D24: Waste Tank Indicator Light Not Fitted | E24: Toilet Fresh Water Solenoid Not Working | G24: Cabin Fan Not Working | I24: Shore Power Breakers Not Labeled And No Rail Stopper | J24: Engine Revs Do Not Align
A25: Telly Mute Not Working | B25: Low Level Float Not Working | C25: Missing Salt/Fresh Label At Toilet | D25: Missing Salt/Fresh Label At Toilet | E25: Waste Tank Indicator Not Working | G25: Waste Tank Indicator Light Not Fitted | I25: Engine Harness Not Strapped Up
A26: Nmma Label Needs To Be Mounted | B26: Toilet Anti-Syphen Leaking | C26: Shower Leaking Into Bilge | D26: Shower Leaking Into Bilge | E26: Cabin Fan Not Working | G26: Missing Salt/Fresh Label At Toilet | I26: Engine Revs Do Not Align
A27: Inverter Alarm Not Working | B27: Toilet Fresh Water Solenoid Not Working | C27: Toilet Salt/Fresh Is Cross Wired | D27: Toilet Salt/Fresh Is Cross Wired | E27: Waste Tank Indicator Light Not Fitted | G27: Shower Leaking Into Bilge
A28: Aircon Switching On Wrong Pump | B28: Waste Tank Indicator Not Working | C28: Shower Head Leaking | D28: Shower Head Leaking | E28: Missing Salt/Fresh Label At Toilet | G28: Toilet Salt/Fresh Is Cross Wired
A29: Incomplete Wiring Behind Acdc Panel | B29: Cabin Fan Not Working | C29: Toilet Flush Defective | D29: Toilet Flush Defective | E29: Shower Leaking Into Bilge | G29: Shower Head Leaking
A30: Incomplete Wiring At Main Saloon Db | B30: Waste Tank Indicator Light Not Fitted | C30: Cabin Door Missing A Magnet Stopper | D30: Cabin Door Missing A Magnet Stopper | E30: Toilet Salt/Fresh Is Cross Wired | G30: Toilet Flush Defective
A31: Aircon Not Working | B31: Missing Salt/Fresh Label At Toilet | C31: Toilet Flush Is Cross Wired | D31: Toilet Flush Is Cross Wired | E31: Shower Head Leaking | G31: Incorrect Wiring On Finder Relay For Genset
A32: Saloon Door Needs To Be Set | B32: Shower Leaking Into Bilge | D32: Aircon Pump Pipes Leaking | E32: Toilet Flush Defective | G32: Cabin Door Missing A Magnet Stopper
A33: Aircon Not Draining | B33: Toilet Salt/Fresh Is Cross Wired | D33: Aircon Connection Box Not Labeled | E33: Cabin Door Missing A Magnet Stopper | G33: Toilet Flush Is Cross Wired
A34: Incomplete Wiring On Db | B34: Shower Head Leaking | D34: Aircon Box Incorrectly Wired | E34: Leak On Water Heater | G34: Battery Cover Not Fitted
A35: Speakers Not Working | B35: Toilet Flush Defective | D35: Missing Timmer Module For Aircon Relays | E35: Toilet Flush Is Cross Wired
B36: Cabin Door Missing A Magnet Stopper
B37: Leak On Water Heater
B38: Toilet Flush Is Cross Wired
B39: Morse Control Cables Are Badly Routed
